Workbook

Sheet Summary
A1: Rooted Capital global sleeve: values screen (scored companies)
A2: As of Oct 23, 2026 · 63 companies scored in 14 country-sectors · 7 dropped by the team (see 'Dropped') · values filter only
A4: Country | B4: Sector | C4: Companies scored | D4: Pass | E4: Fail | F4: Top company | G4: Top final score | H4: Average final score
A5: Denmark | B5: Financials | C5: =COUNTIFS('All scored'!$A$2:$A$64,A5,'All scored'!$B$2:$B$64,B5) -> 4 | D5: =COUNTIFS('All scored'!$A$2:$A$64,A5,'All scored'!$B$2:$B$64,B5,'All scored'!$M$2:$M$64,"Pass") -> 2 | E5: =COUNTIFS('All scored'!$A$2:$A$64,A5,'All scored'!$B$2:$B$64,B5,'All scored'!$M$2:$M$64,"Fail") -> 2 | F5: =INDEX('All scored'!$D$2:$D$64,MATCH(1,INDEX(('All scored'!$A$2:$A$64=A5)*('All scored'!$B$2:$B$64=B5)*('All scored'!$L$2:$L$64=1),0),0)) -> Danske Bank | G5: =SUMPRODUCT(MAX(('All scored'!$A$2:$A$64=A5)*('All scored'!$B$2:$B$64=B5)*'All scored'!$K$2:$K$64)) -> 32 | H5: =AVERAGEIFS('All scored'!$K$2:$K$64,'All scored'!$A$2:$A$64,A5,'All scored'!$B$2:$B$64,B5) -> 26
A6: Denmark | B6: Health Care | C6: =COUNTIFS('All scored'!$A$2:$A$64,A6,'All scored'!$B$2:$B$64,B6) -> 6 | D6: =COUNTIFS('All scored'!$A$2:$A$64,A6,'All scored'!$B$2:$B$64,B6,'All scored'!$M$2:$M$64,"Pass") -> 3 | E6: =COUNTIFS('All scored'!$A$2:$A$64,A6,'All scored'!$B$2:$B$64,B6,'All scored'!$M$2:$M$64,"Fail") -> 3 | F6: =INDEX('All scored'!$D$2:$D$64,MATCH(1,INDEX(('All scored'!$A$2:$A$64=A6)*('All scored'!$B$2:$B$64=B6)*('All scored'!$L$2:$L$64=1),0),0)) -> Demant | G6: =SUMPRODUCT(MAX(('All scored'!$A$2:$A$64=A6)*('All scored'!$B$2:$B$64=B6)*'All scored'!$K$2:$K$64)) -> 31 | H6: =AVERAGEIFS('All scored'!$K$2:$K$64,'All scored'!$A$2:$A$64,A6,'All scored'!$B$2:$B$64,B6) -> 20.5
A7: Denmark | B7: Industrials | C7: =COUNTIFS('All scored'!$A$2:$A$64,A7,'All scored'!$B$2:$B$64,B7) -> 4 | D7: =COUNTIFS('All scored'!$A$2:$A$64,A7,'All scored'!$B$2:$B$64,B7,'All scored'!$M$2:$M$64,"Pass") -> 3 | E7: =COUNTIFS('All scored'!$A$2:$A$64,A7,'All scored'!$B$2:$B$64,B7,'All scored'!$M$2:$M$64,"Fail") -> 1 | F7: =INDEX('All scored'!$D$2:$D$64,MATCH(1,INDEX(('All scored'!$A$2:$A$64=A7)*('All scored'!$B$2:$B$64=B7)*('All scored'!$L$2:$L$64=1),0),0)) -> Vestas Wind Systems | G7: =SUMPRODUCT(MAX(('All scored'!$A$2:$A$64=A7)*('All scored'!$B$2:$B$64=B7)*'All scored'!$K$2:$K$64)) -> 26 | H7: =AVERAGEIFS('All scored'!$K$2:$K$64,'All scored'!$A$2:$A$64,A7,'All scored'!$B$2:$B$64,B7) -> 22.75
A8: Switzerland | B8: Health Care | C8: =COUNTIFS('All scored'!$A$2:$A$64,A8,'All scored'!$B$2:$B$64,B8) -> 6 | D8: =COUNTIFS('All scored'!$A$2:$A$64,A8,'All scored'!$B$2:$B$64,B8,'All scored'!$M$2:$M$64,"Pass") -> 3 | E8: =COUNTIFS('All scored'!$A$2:$A$64,A8,'All scored'!$B$2:$B$64,B8,'All scored'!$M$2:$M$64,"Fail") -> 3 | F8: =INDEX('All scored'!$D$2:$D$64,MATCH(1,INDEX(('All scored'!$A$2:$A$64=A8)*('All scored'!$B$2:$B$64=B8)*('All scored'!$L$2:$L$64=1),0),0)) -> Straumann | G8: =SUMPRODUCT(MAX(('All scored'!$A$2:$A$64=A8)*('All scored'!$B$2:$B$64=B8)*'All scored'!$K$2:$K$64)) -> 43 | H8: =AVERAGEIFS('All scored'!$K$2:$K$64,'All scored'!$A$2:$A$64,A8,'All scored'!$B$2:$B$64,B8) -> 32.833333
A9: Switzerland | B9: Industrials | C9: =COUNTIFS('All scored'!$A$2:$A$64,A9,'All scored'!$B$2:$B$64,B9) -> 4 | D9: =COUNTIFS('All scored'!$A$2:$A$64,A9,'All scored'!$B$2:$B$64,B9,'All scored'!$M$2:$M$64,"Pass") -> 2 | E9: =COUNTIFS('All scored'!$A$2:$A$64,A9,'All scored'!$B$2:$B$64,B9,'All scored'!$M$2:$M$64,"Fail") -> 2 | F9: =INDEX('All scored'!$D$2:$D$64,MATCH(1,INDEX(('All scored'!$A$2:$A$64=A9)*('All scored'!$B$2:$B$64=B9)*('All scored'!$L$2:$L$64=1),0),0)) -> Schindler Group | G9: =SUMPRODUCT(MAX(('All scored'!$A$2:$A$64=A9)*('All scored'!$B$2:$B$64=B9)*'All scored'!$K$2:$K$64)) -> 30 | H9: =AVERAGEIFS('All scored'!$K$2:$K$64,'All scored'!$A$2:$A$64,A9,'All scored'!$B$2:$B$64,B9) -> 25.5
A10: Switzerland | B10: Materials | C10: =COUNTIFS('All scored'!$A$2:$A$64,A10,'All scored'!$B$2:$B$64,B10) -> 3 | D10: =COUNTIFS('All scored'!$A$2:$A$64,A10,'All scored'!$B$2:$B$64,B10,'All scored'!$M$2:$M$64,"Pass") -> 2 | E10: =COUNTIFS('All scored'!$A$2:$A$64,A10,'All scored'!$B$2:$B$64,B10,'All scored'!$M$2:$M$64,"Fail") -> 1 | F10: =INDEX('All scored'!$D$2:$D$64,MATCH(1,INDEX(('All scored'!$A$2:$A$64=A10)*('All scored'!$B$2:$B$64=B10)*('All scored'!$L$2:$L$64=1),0),0)) -> Givaudan | G10: =SUMPRODUCT(MAX(('All scored'!$A$2:$A$64=A10)*('All scored'!$B$2:$B$64=B10)*'All scored'!$K$2:$K$64)) -> 57 | H10: =AVERAGEIFS('All scored'!$K$2:$K$64,'All scored'!$A$2:$A$64,A10,'All scored'!$B$2:$B$64,B10) -> 46.666667
A11: Taiwan | B11: Financials | C11: =COUNTIFS('All scored'!$A$2:$A$64,A11,'All scored'!$B$2:$B$64,B11) -> 6 | D11: =COUNTIFS('All scored'!$A$2:$A$64,A11,'All scored'!$B$2:$B$64,B11,'All scored'!$M$2:$M$64,"Pass") -> 3 | E11: =COUNTIFS('All scored'!$A$2:$A$64,A11,'All scored'!$B$2:$B$64,B11,'All scored'!$M$2:$M$64,"Fail") -> 3 | F11: =INDEX('All scored'!$D$2:$D$64,MATCH(1,INDEX(('All scored'!$A$2:$A$64=A11)*('All scored'!$B$2:$B$64=B11)*('All scored'!$L$2:$L$64=1),0),0)) -> Fubon Financial | G11: =SUMPRODUCT(MAX(('All scored'!$A$2:$A$64=A11)*('All scored'!$B$2:$B$64=B11)*'All scored'!$K$2:$K$64)) -> 57 | H11: =AVERAGEIFS('All scored'!$K$2:$K$64,'All scored'!$A$2:$A$64,A11,'All scored'!$B$2:$B$64,B11) -> 50.166667
A12: Taiwan | B12: Information Technology | C12: =COUNTIFS('All scored'!$A$2:$A$64,A12,'All scored'!$B$2:$B$64,B12) -> 8 | D12: =COUNTIFS('All scored'!$A$2:$A$64,A12,'All scored'!$B$2:$B$64,B12,'All scored'!$M$2:$M$64,"Pass") -> 5 | E12: =COUNTIFS('All scored'!$A$2:$A$64,A12,'All scored'!$B$2:$B$64,B12,'All scored'!$M$2:$M$64,"Fail") -> 3 | F12: =INDEX('All scored'!$D$2:$D$64,MATCH(1,INDEX(('All scored'!$A$2:$A$64=A12)*('All scored'!$B$2:$B$64=B12)*('All scored'!$L$2:$L$64=1),0),0)) -> ASUS | G12: =SUMPRODUCT(MAX(('All scored'!$A$2:$A$64=A12)*('All scored'!$B$2:$B$64=B12)*'All scored'!$K$2:$K$64)) -> 54 | H12: =AVERAGEIFS('All scored'!$K$2:$K$64,'All scored'!$A$2:$A$64,A12,'All scored'!$B$2:$B$64,B12) -> 37.75
A13: Indonesia | B13: Communication Services | C13: =COUNTIFS('All scored'!$A$2:$A$64,A13,'All scored'!$B$2:$B$64,B13) -> 3 | D13: =COUNTIFS('All scored'!$A$2:$A$64,A13,'All scored'!$B$2:$B$64,B13,'All scored'!$M$2:$M$64,"Pass") -> 2 | E13: =COUNTIFS('All scored'!$A$2:$A$64,A13,'All scored'!$B$2:$B$64,B13,'All scored'!$M$2:$M$64,"Fail") -> 1 | F13: =INDEX('All scored'!$D$2:$D$64,MATCH(1,INDEX(('All scored'!$A$2:$A$64=A13)*('All scored'!$B$2:$B$64=B13)*('All scored'!$L$2:$L$64=1),0),0)) -> Elang Mahkota Teknologi | G13: =SUMPRODUCT(MAX(('All scored'!$A$2:$A$64=A13)*('All scored'!$B$2:$B$64=B13)*'All scored'!$K$2:$K$64)) -> 57 | H13: =AVERAGEIFS('All scored'!$K$2:$K$64,'All scored'!$A$2:$A$64,A13,'All scored'!$B$2:$B$64,B13) -> 44
A14: Indonesia | B14: Consumer Staples | C14: =COUNTIFS('All scored'!$A$2:$A$64,A14,'All scored'!$B$2:$B$64,B14) -> 4 | D14: =COUNTIFS('All scored'!$A$2:$A$64,A14,'All scored'!$B$2:$B$64,B14,'All scored'!$M$2:$M$64,"Pass") -> 2 | E14: =COUNTIFS('All scored'!$A$2:$A$64,A14,'All scored'!$B$2:$B$64,B14,'All scored'!$M$2:$M$64,"Fail") -> 2 | F14: =INDEX('All scored'!$D$2:$D$64,MATCH(1,INDEX(('All scored'!$A$2:$A$64=A14)*('All scored'!$B$2:$B$64=B14)*('All scored'!$L$2:$L$64=1),0),0)) -> Astra Agro Lestari | G14: =SUMPRODUCT(MAX(('All scored'!$A$2:$A$64=A14)*('All scored'!$B$2:$B$64=B14)*'All scored'!$K$2:$K$64)) -> 35 | H14: =AVERAGEIFS('All scored'!$K$2:$K$64,'All scored'!$A$2:$A$64,A14,'All scored'!$B$2:$B$64,B14) -> 31.5
A15: Indonesia | B15: Financials | C15: =COUNTIFS('All scored'!$A$2:$A$64,A15,'All scored'!$B$2:$B$64,B15) -> 2 | D15: =COUNTIFS('All scored'!$A$2:$A$64,A15,'All scored'!$B$2:$B$64,B15,'All scored'!$M$2:$M$64,"Pass") -> 1 | E15: =COUNTIFS('All scored'!$A$2:$A$64,A15,'All scored'!$B$2:$B$64,B15,'All scored'!$M$2:$M$64,"Fail") -> 1 | F15: =INDEX('All scored'!$D$2:$D$64,MATCH(1,INDEX(('All scored'!$A$2:$A$64=A15)*('All scored'!$B$2:$B$64=B15)*('All scored'!$L$2:$L$64=1),0),0)) -> Bank Mandiri | G15: =SUMPRODUCT(MAX(('All scored'!$A$2:$A$64=A15)*('All scored'!$B$2:$B$64=B15)*'All scored'!$K$2:$K$64)) -> 56 | H15: =AVERAGEIFS('All scored'!$K$2:$K$64,'All scored'!$A$2:$A$64,A15,'All scored'!$B$2:$B$64,B15) -> 54.5
A16: Singapore | B16: Financials | C16: =COUNTIFS('All scored'!$A$2:$A$64,A16,'All scored'!$B$2:$B$64,B16) -> 5 | D16: =COUNTIFS('All scored'!$A$2:$A$64,A16,'All scored'!$B$2:$B$64,B16,'All scored'!$M$2:$M$64,"Pass") -> 3 | E16: =COUNTIFS('All scored'!$A$2:$A$64,A16,'All scored'!$B$2:$B$64,B16,'All scored'!$M$2:$M$64,"Fail") -> 2 | F16: =INDEX('All scored'!$D$2:$D$64,MATCH(1,INDEX(('All scored'!$A$2:$A$64=A16)*('All scored'!$B$2:$B$64=B16)*('All scored'!$L$2:$L$64=1),0),0)) -> UOB | G16: =SUMPRODUCT(MAX(('All scored'!$A$2:$A$64=A16)*('All scored'!$B$2:$B$64=B16)*'All scored'!$K$2:$K$64)) -> 53 | H16: =AVERAGEIFS('All scored'!$K$2:$K$64,'All scored'!$A$2:$A$64,A16,'All scored'!$B$2:$B$64,B16) -> 43.6
... A18: Singapore | B18: Real Estate | C18: =COUNTIFS('All scored'!$A$2:$A$64,A18,'All scored'!$B$2:$B$64,B18) -> 4 | D18: =COUNTIFS('All scored'!$A$2:$A$64,A18,'All scored'!$B$2:$B$64,B18,'All scored'!$M$2:$M$64,"Pass") -> 2 | E18: =COUNTIFS('All scored'!$A$2:$A$64,A18,'All scored'!$B$2:$B$64,B18,'All scored'!$M$2:$M$64,"Fail") -> 2 | F18: =INDEX('All scored'!$D$2:$D$64,MATCH(1,INDEX(('All scored'!$A$2:$A$64=A18)*('All scored'!$B$2:$B$64=B18)*('All scored'!$L$2:$L$64=1),0),0)) -> CapitaLand Integrated Commercial Trust | G18: =SUMPRODUCT(MAX(('All scored'!$A$2:$A$64=A18)*('All scored'!$B$2:$B$64=B18)*'All scored'!$K$2:$K$64)) -> 34 | H18: =AVERAGEIFS('All scored'!$K$2:$K$64,'All scored'!$A$2:$A$64,A18,'All scored'!$B$2:$B$64,B18) -> 21.5
A19: Total | C19: =SUM(C5:C18) -> 63 | D19: =SUM(D5:D18) -> 35 | E19: =SUM(E5:E18) -> 28 | H19: =AVERAGE('All scored'!$K$2:$K$64) -> 34.142857
A21: Pass = top half of the country-sector by final score, ties included. Ties for the top spot show the first company listed; see 'All scored' for full ranks.
A22: Sources: fiscal-2025 annual reports from official exchange filing sites (Nasdaq Copenhagen, MOPS, SGX) or company websites; 20-Fs from SEC EDGAR for Genmab, Alcon and Telkom.

Sheet Pass list
A1: Country | B1: Sector | C1: Rank | D1: Ticker | E1: Company | F1: Final score | G1: Strongest theme
A2: Denmark | B2: Financials | C2: 1 | D2: DANSKE.CO | E2: Danske Bank | F2: 32 | G2: Community 3 from Leadership development programme for employees, expanded in 2025 and m
A3: Denmark | B3: Financials | C3: 2 | D3: ALSYDB.CO | E3: AL Sydbank A/S | F3: 30 | G3: Cross-cultural 2 from Dedicated Sunflower phone line where trained staff assist customers wi
A4: Denmark | B4: Health Care | C4: 1 | D4: DEMANT.CO | E4: Demant | F4: 31 | G4: Cross-cultural 4 from Core business sells hearing aids (assistive technology) and runs clini
A5: Denmark | B5: Health Care | C5: 2 | D5: HLUN-B.CO | E5: Lundbeck | F5: 29 | G5: Community 3 from Enterprise Leadership Program rolled out to train and develop the comp
A6: Denmark | B6: Health Care | C6: 3 | D6: BAVA.CO | E6: Bavarian Nordic | F6: 27 | G6: Cross-cultural 3 from Lowest-price mpox vaccine access for low- and lower-middle-income coun
A7: Denmark | B7: Industrials | C7: 1 | D7: VWS.CO | E7: Vestas Wind Systems | F7: 26 | G7: Entrepreneurship 2 from Technical training, capacity building and entrepreneurship courses for
A8: Denmark | B8: Industrials | C8: 2 | D8: DNORD.CO | E8: D/S Norden | F8: 23 | G8: Cross-cultural 2 from Bias-mitigating recruitment practices, including diverse panels and a
A9: Denmark | B9: Industrials | C9: 2 | D9: MAERSK-B.CO | E9: Maersk | F9: 23 | G9: Cross-cultural 2 from Whistleblower mechanism available in many languages for employees and
A10: Switzerland | B10: Health Care | C10: 1 | D10: STMN.SW | E10: Straumann | F10: 43 | G10: Community 3 from Global clinical education programme for dental professionals, run with
A11: Switzerland | B11: Health Care | C11: 2 | D11: SOON.SW | E11: Sonova | F11: 40 | G11: Cross-cultural 3 from Global employee resource groups, including OutLoud and Hearing Loss ne
A12: Switzerland | B12: Health Care | C12: 3 | D12: GALD.SW | E12: Galderma Group | F12: 36 | G12: Community 3 from Galderma Aesthetic Injector Network (GAIN), a global hands-on clinical
A13: Switzerland | B13: Industrials | C13: 1 | D13: SCHN.SW | E13: Schindler Group | F13: 30 | G13: Cross-cultural 2 from Accessibility features (induction loops, voice signaling, Braille) ins
... A36: Singapore | B36: Real Estate | C36: 2 | D36: K71U.SI | E36: Keppel REIT | F36: 20 | G36: Cross-cultural 2 from Training on unconscious bias and inclusive leadership for employees
A38: Snapshot of the 'Values result' column on Oct 23, 2026 (sorted by country, sector, rank).

Sheet All scored
A1: Country | B1: Sector | C1: Ticker | D1: Company | E1: Creativity (0-5) | F1: Community (0-5) | G1: Cross-cultural (0-5) | H1: Entrepreneurship (0-5) | I1: Alignment score (0-100) | J1: Red flag deduction | K1: Final score | L1: Country-sector rank | M1: Values result | N1: Red flags | O1: Third component (TBD) | P1: Thin-coverage themes | Q1: Score source | R1: Document | S1: Fiscal year | T1: Source site | U1: Report link | V1: Language | W1: Words read | X1: Notes | Y1: Flags for review
A2: Denmark | B2: Financials | C2: DANSKE.CO | D2: Danske Bank | E2: 0 | F2: 3 | G2: 2 | H2: 2 | I2: =E2/5*35+F2/5*30+G2/5*20+H2/5*15 -> 32 | J2: 0 | K2: =MAX(0,I2-J2) -> 32 | L2: =COUNTIFS($A$2:$A$64,A2,$B$2:$B$64,B2,$K$2:$K$64,">"&K2)+1 -> 1 | M2: =IF(L2<=CEILING(COUNTIFS($A$2:$A$64,A2,$B$2:$B$64,B2)/2,1),"Pass","Fail") -> Pass | Q2: Annual report 2025 | R2: Annual report | S2: 2025 | T2: company website | U2: https://danskebank.com/-/media/danske-bank-com/file-cloud/2026/2/annual-report-2025.pdf?rev=16af459cfa094b8ab365a911a324f7f2 | V2: English | W2: 39956 | X2: Top half of Denmark Financials; Community 3 from Leadership development programme for employees, expanded in 2025 and m; red flag: none; Discloses internally substantiated discrimination/harassment cases; not a red flag under the rule.
A3: Denmark | B3: Financials | C3: ALSYDB.CO | D3: AL Sydbank A/S | E3: 1 | F3: 2 | G3: 2 | H3: 1 | I3: =E3/5*35+F3/5*30+G3/5*20+H3/5*15 -> 30 | J3: 0 | K3: =MAX(0,I3-J3) -> 30 | L3: =COUNTIFS($A$2:$A$64,A3,$B$2:$B$64,B3,$K$2:$K$64,">"&K3)+1 -> 2 | M3: =IF(L3<=CEILING(COUNTIFS($A$2:$A$64,A3,$B$2:$B$64,B3)/2,1),"Pass","Fail") -> Pass | Q3: Annual report 2025 | R3: Annual report | S3: 2025 | T3: Nasdaq Copenhagen company announcements | U3: https://attachment.news.eu.nasdaq.com/a636006377807c5474acd3b1ab00500e5 | V3: English | W3: 15216 | X3: Top half of Denmark Financials; Cross-cultural 2 from Dedicated Sunflower phone line where trained staff assist customers wi; red flag: none
A4: Denmark | B4: Financials | C4: JYSK.CO | D4: Jyske Bank | E4: 0 | F4: 2 | G4: 2 | H4: 1 | I4: =E4/5*35+F4/5*30+G4/5*20+H4/5*15 -> 23 | J4: 0 | K4: =MAX(0,I4-J4) -> 23 | L4: =COUNTIFS($A$2:$A$64,A4,$B$2:$B$64,B4,$K$2:$K$64,">"&K4)+1 -> 3 | M4: =IF(L4<=CEILING(COUNTIFS($A$2:$A$64,A4,$B$2:$B$64,B4)/2,1),"Pass","Fail") -> Fail | Q4: Annual report 2025 | R4: Annual report | S4: 2025 | T4: Nasdaq Copenhagen company announcements | U4: https://attachment.news.eu.nasdaq.com/a11687649947912d72fafbdc8f0845e19 | V4: English | W4: 17877 | X4: Not in top half of Denmark Financials; Cross-cultural 2 from Participation in the Sunflower programme to support customers with inv; red flag: none | Y4: TOC fallback (no usable table of contents): keyword paragraphs across the whole report; skipped 32 of 264 pages (risk, number pages, financial statements from page 257, except 8 governance/sustainability page(s) after them)
A5: Denmark | B5: Financials | C5: DJUR.CO | D5: Djurslands Bank A/S | E5: 0 | F5: 2 | G5: 1 | H5: 1 | I5: =E5/5*35+F5/5*30+G5/5*20+H5/5*15 -> 19 | J5: 0 | K5: =MAX(0,I5-J5) -> 19 | L5: =COUNTIFS($A$2:$A$64,A5,$B$2:$B$64,B5,$K$2:$K$64,">"&K5)+1 -> 4 | M5: =IF(L5<=CEILING(COUNTIFS($A$2:$A$64,A5,$B$2:$B$64,B5)/2,1),"Pass","Fail") -> Fail | P5: community, cross-cultural | Q5: Annual report 2025 | R5: Annual report | S5: 2025 | T5: Nasdaq Copenhagen company announcements | U5: https://attachment.news.eu.nasdaq.com/a610db5d4df88710ac547817939aacd8f | V5: Non-English | W5: 10204 | X5: Not in top half of Denmark Financials; Community 2 from Structured professional and personal skills development for all employ; red flag: none; non-English source | Y5: coverage insufficient (community, cross_cultural); second look: no standalone report found
A6: Denmark | B6: Health Care | C6: DEMANT.CO | D6: Demant | E6: 0 | F6: 2 | G6: 4 | H6: 1 | I6: =E6/5*35+F6/5*30+G6/5*20+H6/5*15 -> 31 | J6: 0 | K6: =MAX(0,I6-J6) -> 31 | L6: =COUNTIFS($A$2:$A$64,A6,$B$2:$B$64,B6,$K$2:$K$64,">"&K6)+1 -> 1 | M6: =IF(L6<=CEILING(COUNTIFS($A$2:$A$64,A6,$B$2:$B$64,B6)/2,1),"Pass","Fail") -> Pass | Q6: Annual report 2025 | R6: Annual report | S6: 2025 | T6: company website | U6: https://assets-we.cas.dgs.com/-/media/demant/shared/new-library-2022/financial-reports/annual-report-english/demant-annual-report-2025.pdf?la=en&rev=AE32&hash=F68551D4B2CB09858AD389A748D55FF6 | V6: English | W6: 34662 | X6: Top half of Denmark Health Care; Cross-cultural 4 from Core business sells hearing aids (assistive technology) and runs clini; red flag: none; Discloses internally substantiated discrimination and/or harassment cases; not a red flag under the rule.
A7: Denmark | B7: Health Care | C7: HLUN-B.CO | D7: Lundbeck | E7: 0 | F7: 3 | G7: 2 | H7: 1 | I7: =E7/5*35+F7/5*30+G7/5*20+H7/5*15 -> 29 | J7: 0 | K7: =MAX(0,I7-J7) -> 29 | L7: =COUNTIFS($A$2:$A$64,A7,$B$2:$B$64,B7,$K$2:$K$64,">"&K7)+1 -> 2 | M7: =IF(L7<=CEILING(COUNTIFS($A$2:$A$64,A7,$B$2:$B$64,B7)/2,1),"Pass","Fail") -> Pass | Q7: Annual report 2025 | R7: Annual report | S7: 2025 | T7: company website | U7: https://www.lundbeck.com/content/dam/lundbeck-com/masters/global-site/annual-reporting/2025/Lundbeck_Annual_Report_2025.pdf | V7: English | W7: 40149 | X7: Top half of Denmark Health Care; Community 3 from Enterprise Leadership Program rolled out to train and develop the comp; red flag: none; Discloses internally substantiated harassment and/or discrimination cases; not a red flag under the rule. | Y7: E5: figure(s) not found near the quote, removed: 93 community: needs human review: figure(s) removed from cited evidence E5; the level may be lower
A8: Denmark | B8: Health Care | C8: BAVA.CO | D8: Bavarian Nordic | E8: 0 | F8: 2 | G8: 3 | H8: 1 | I8: =E8/5*35+F8/5*30+G8/5*20+H8/5*15 -> 27 | J8: 0 | K8: =MAX(0,I8-J8) -> 27 | L8: =COUNTIFS($A$2:$A$64,A8,$B$2:$B$64,B8,$K$2:$K$64,">"&K8)+1 -> 3 | M8: =IF(L8<=CEILING(COUNTIFS($A$2:$A$64,A8,$B$2:$B$64,B8)/2,1),"Pass","Fail") -> Pass | Q8: Annual report 2025 | R8: Annual report | S8: 2025 | T8: company website | U8: https://www.bavarian-nordic.com/media/380028/bn_annual_report_2025.pdf | V8: English | W8: 39980 | X8: Top half of Denmark Health Care; Cross-cultural 3 from Lowest-price mpox vaccine access for low- and lower-middle-income coun; red flag: none; Discloses internally substantiated discrimination, including harassment cases; not a red flag under the rule.
A9: Denmark | B9: Health Care | C9: ZEAL.CO | D9: Zealand Pharma | E9: 0 | F9: 2 | G9: 2 | H9: 1 | I9: =E9/5*35+F9/5*30+G9/5*20+H9/5*15 -> 23 | J9: 0 | K9: =MAX(0,I9-J9) -> 23 | L9: =COUNTIFS($A$2:$A$64,A9,$B$2:$B$64,B9,$K$2:$K$64,">"&K9)+1 -> 4 | M9: =IF(L9<=CEILING(COUNTIFS($A$2:$A$64,A9,$B$2:$B$64,B9)/2,1),"Pass","Fail") -> Fail | Q9: Annual report 2025 | R9: Annual report | S9: 2025 | T9: company website | U9: https://www.zealandpharma.com/media/2oeew4jl/zealand-pharma-annual-report-2025.pdf | V9: English | W9: 24438 | X9: Not in top half of Denmark Health Care; Cross-cultural 2 from Inclusiveness Index built into the employee engagement survey to give ; red flag: none
A10: Denmark | B10: Health Care | C10: CHEMM.CO | D10: ChemoMetec | E10: 0 | F10: 1 | G10: 1 | H10: 1 | I10: =E10/5*35+F10/5*30+G10/5*20+H10/5*15 -> 13 | J10: 0 | K10: =MAX(0,I10-J10) -> 13 | L10: =COUNTIFS($A$2:$A$64,A10,$B$2:$B$64,B10,$K$2:$K$64,">"&K10)+1 -> 5 | M10: =IF(L10<=CEILING(COUNTIFS($A$2:$A$64,A10,$B$2:$B$64,B10)/2,1),"Pass","Fail") -> Fail | Q10: Annual report 2025 | R10: Annual report | S10: 2025 | T10: Nasdaq Copenhagen company announcements | U10: https://attachment.news.eu.nasdaq.com/a772ca2d52624dd57c81a282b8e1fb8aa | V10: English | W10: 21495 | X10: Not in top half of Denmark Health Care; no theme above 1; red flag: none
A11: Denmark | B11: Health Care | C11: GMAB | D11: Genmab | E11: 0 | F11: 0 | G11: 0 | H11: 0 | I11: =E11/5*35+F11/5*30+G11/5*20+H11/5*15 -> 0 | J11: 0 | K11: =MAX(0,I11-J11) -> 0 | L11: =COUNTIFS($A$2:$A$64,A11,$B$2:$B$64,B11,$K$2:$K$64,">"&K11)+1 -> 6 | M11: =IF(L11<=CEILING(COUNTIFS($A$2:$A$64,A11,$B$2:$B$64,B11)/2,1),"Pass","Fail") -> Fail | P11: community, cross-cultural | Q11: 20-F 2025 | R11: 20-F | S11: 2025 | T11: SEC EDGAR | U11: https://www.sec.gov/Archives/edgar/data/1434265/000143426526000014/gmab-20251231_d2.htm | V11: English | W11: 24493 | X11: Not in top half of Denmark Health Care; no theme above 1; red flag: none | Y11: coverage insufficient (community, cross_cultural); second look: no standalone report found
A12: Denmark | B12: Industrials | C12: VWS.CO | D12: Vestas Wind Systems | E12: 0 | F12: 2 | G12: 2 | H12: 2 | I12: =E12/5*35+F12/5*30+G12/5*20+H12/5*15 -> 26 | J12: 0 | K12: =MAX(0,I12-J12) -> 26 | L12: =COUNTIFS($A$2:$A$64,A12,$B$2:$B$64,B12,$K$2:$K$64,">"&K12)+1 -> 1 | M12: =IF(L12<=CEILING(COUNTIFS($A$2:$A$64,A12,$B$2:$B$64,B12)/2,1),"Pass","Fail") -> Pass | Q12: Annual report 2025 | R12: Annual report | S12: 2025 | T12: company website | U12: https://www.vestas.com/content/dam/vestas-com/global/en/investor/reports-and-presentations/financial/2025/fy-2025/Vestas%20Annual%20Report%202025.pdf.coredownload.inline.pdf | V12: English | W12: 40183 | X12: Top half of Denmark Industrials; Entrepreneurship 2 from Technical training, capacity building and entrepreneurship courses for; red flag: none; Discloses internally substantiated discrimination/harassment/labour rights (ethicsline social and human rights complaints) cases; not a red flag under the rule.
A13: Denmark | B13: Industrials | C13: DNORD.CO | D13: D/S Norden | E13: 0 | F13: 2 | G13: 2 | H13: 1 | I13: =E13/5*35+F13/5*30+G13/5*20+H13/5*15 -> 23 | J13: 0 | K13: =MAX(0,I13-J13) -> 23 | L13: =COUNTIFS($A$2:$A$64,A13,$B$2:$B$64,B13,$K$2:$K$64,">"&K13)+1 -> 2 | M13: =IF(L13<=CEILING(COUNTIFS($A$2:$A$64,A13,$B$2:$B$64,B13)/2,1),"Pass","Fail") -> Pass | Q13: Annual report 2025 | R13: Annual report | S13: 2025 | T13: Nasdaq Copenhagen company announcements | U13: https://attachment.news.eu.nasdaq.com/ac6824c31a47a615477d702aedbbdb9ad#esef | V13: English | W13: 19517 | X13: Top half of Denmark Industrials; Cross-cultural 2 from Bias-mitigating recruitment practices, including diverse panels and a ; red flag: none
A14: Denmark | B14: Industrials | C14: MAERSK-B.CO | D14: Maersk | E14: 0 | F14: 2 | G14: 2 | H14: 1 | I14: =E14/5*35+F14/5*30+G14/5*20+H14/5*15 -> 23 | J14: 0 | K14: =MAX(0,I14-J14) -> 23 | L14: =COUNTIFS($A$2:$A$64,A14,$B$2:$B$64,B14,$K$2:$K$64,">"&K14)+1 -> 2 | M14: =IF(L14<=CEILING(COUNTIFS($A$2:$A$64,A14,$B$2:$B$64,B14)/2,1),"Pass","Fail") -> Pass | Q14: Annual report 2025 | R14: Annual report | S14: 2025 | T14: Nasdaq Copenhagen company announcements | U14: https://attachment.news.eu.nasdaq.com/aa5bc3ccc5e259aa01dbe8bff4f0995b1 | V14: English | W14: 20969 | X14: Top half of Denmark Industrials; Cross-cultural 2 from Whistleblower mechanism available in many languages for employees and ; red flag: none; Discloses internally substantiated discrimination cases; not a red flag under the rule.
A15: Denmark | B15: Industrials | C15: NTG.CO | D15: NTG Nordic Transport Group A/S | E15: 0 | F15: 2 | G15: 1 | H15: 1 | I15: =E15/5*35+F15/5*30+G15/5*20+H15/5*15 -> 19 | J15: 0 | K15: =MAX(0,I15-J15) -> 19 | L15: =COUNTIFS($A$2:$A$64,A15,$B$2:$B$64,B15,$K$2:$K$64,">"&K15)+1 -> 4 | M15: =IF(L15<=CEILING(COUNTIFS($A$2:$A$64,A15,$B$2:$B$64,B15)/2,1),"Pass","Fail") -> Fail | Q15: Annual report 2025 | R15: Annual report | S15: 2025 | T15: Nasdaq Copenhagen company announcements | U15: https://attachment.news.eu.nasdaq.com/a35279cd1e1c3779db793f83af61e92e8 | V15: English | W15: 18578 | X15: Not in top half of Denmark Industrials; Community 2 from New central People & Culture function to develop employees across the ; red flag: none
A16: Switzerland | B16: Health Care | C16: STMN.SW | D16: Straumann | E16: 2 | F16: 3 | G16: 2 | H16: 1 | I16: =E16/5*35+F16/5*30+G16/5*20+H16/5*15 -> 43 | J16: 0 | K16: =MAX(0,I16-J16) -> 43 | L16: =COUNTIFS($A$2:$A$64,A16,$B$2:$B$64,B16,$K$2:$K$64,">"&K16)+1 -> 1 | M16: =IF(L16<=CEILING(COUNTIFS($A$2:$A$64,A16,$B$2:$B$64,B16)/2,1),"Pass","Fail") -> Pass | Q16: Annual report 2025 | R16: Annual report | S16: 2025 | T16: company website | U16: https://www.straumann.com/content/dam/media-center/group/en/documents/annual-report/2025/Straumann_AR25.pdf | V16: English | W16: 40146 | X16: Top half of Switzerland Health Care; Community 3 from Global clinical education programme for dental professionals, run with; red flag: none; Discloses internally substantiated discrimination and harassment cases; not a red flag under the rule.
A17: Switzerland | B17: Health Care | C17: SOON.SW | D17: Sonova | E17: 1 | F17: 3 | G17: 3 | H17: 1 | I17: =E17/5*35+F17/5*30+G17/5*20+H17/5*15 -> 40 | J17: 0 | K17: =MAX(0,I17-J17) -> 40 | L17: =COUNTIFS($A$2:$A$64,A17,$B$2:$B$64,B17,$K$2:$K$64,">"&K17)+1 -> 2 | M17: =IF(L17<=CEILING(COUNTIFS($A$2:$A$64,A17,$B$2:$B$64,B17)/2,1),"Pass","Fail") -> Pass | Q17: Annual report 2025 | R17: Annual report | S17: 2025 | T17: company website | U17: https://www.sonova.com/wp-content/uploads/2026/05/01_Sonova_AR_25-26_Full_Report_en.pdf | V17: English | W17: 38892 | X17: Top half of Switzerland Health Care; Cross-cultural 3 from Global employee resource groups, including OutLoud and Hearing Loss ne; red flag: none
A18: Switzerland | B18: Health Care | C18: GALD.SW | D18: Galderma Group | E18: 1 | F18: 3 | G18: 2 | H18: 1 | I18: =E18/5*35+F18/5*30+G18/5*20+H18/5*15 -> 36 | J18: 0 | K18: =MAX(0,I18-J18) -> 36 | L18: =COUNTIFS($A$2:$A$64,A18,$B$2:$B$64,B18,$K$2:$K$64,">"&K18)+1 -> 3 | M18: =IF(L18<=CEILING(COUNTIFS($A$2:$A$64,A18,$B$2:$B$64,B18)/2,1),"Pass","Fail") -> Pass | Q18: Annual report 2025 | R18: Annual report | S18: 2025 | T18: company website | U18: https://www.galderma.com/sites/default/files/2026-03/galderma_ar_2025_consolidated-doc_8b_260304_-_full.pdf | V18: English | W18: 23690 | X18: Top half of Switzerland Health Care; Community 3 from Galderma Aesthetic Injector Network (GAIN), a global hands-on clinical; red flag: none
A19: Switzerland | B19: Health Care | C19: SDZ.SW | D19: Sandoz Group | E19: 0 | F19: 3 | G19: 3 | H19: 1 | I19: =E19/5*35+F19/5*30+G19/5*20+H19/5*15 -> 33 | J19: 0 | K19: =MAX(0,I19-J19) -> 33 | L19: =COUNTIFS($A$2:$A$64,A19,$B$2:$B$64,B19,$K$2:$K$64,">"&K19)+1 -> 4 | M19: =IF(L19<=CEILING(COUNTIFS($A$2:$A$64,A19,$B$2:$B$64,B19)/2,1),"Pass","Fail") -> Fail | Q19: Annual report 2025 | R19: Annual report | S19: 2025 | T19: company website | U19: https://sandoz-com.cms.sandoz.com/sites/default/files/Media%20Documents/Sandoz%20Integrated%20Annual%20Report%202025.pdf | V19: English | W19: 24128 | X19: Not in top half of Switzerland Health Care; Cross-cultural 3 from Access program for low- and middle-income countries: lower prices, lic; red flag: none; Discloses internally substantiated harassment cases; not a red flag under the rule.
A20: Switzerland | B20: Health Care | C20: LONN.SW | D20: Lonza | E20: 0 | F20: 2 | G20: 2 | H20: 1 | I20: =E20/5*35+F20/5*30+G20/5*20+H20/5*15 -> 23 | J20: 0 | K20: =MAX(0,I20-J20) -> 23 | L20: =COUNTIFS($A$2:$A$64,A20,$B$2:$B$64,B20,$K$2:$K$64,">"&K20)+1 -> 5 | M20: =IF(L20<=CEILING(COUNTIFS($A$2:$A$64,A20,$B$2:$B$64,B20)/2,1),"Pass","Fail") -> Fail | Q20: Annual report 2025 | R20: Annual report | S20: 2025 | T20: SGX company announcements (secondary listing | U20: ) https://links.sgx.com/1.0.0/corporate-announcements/LJE7WPRJD5EBVAED/881490_Lonza%20Annual%20Report%202025.pdf | V20: English | W20: 18235 | X20: Not in top half of Switzerland Health Care; Cross-cultural 2 from HR practice allowing employees to self-identify as transgender or not ; red flag: none
A21: Switzerland | B21: Health Care | C21: ALC | D21: Alcon | E21: 0 | F21: 2 | G21: 1 | H21: 2 | I21: =E21/5*35+F21/5*30+G21/5*20+H21/5*15 -> 22 | J21: 0 | K21: =MAX(0,I21-J21) -> 22 | L21: =COUNTIFS($A$2:$A$64,A21,$B$2:$B$64,B21,$K$2:$K$64,">"&K21)+1 -> 6 | M21: =IF(L21<=CEILING(COUNTIFS($A$2:$A$64,A21,$B$2:$B$64,B21)/2,1),"Pass","Fail") -> Fail | P21: cross-cultural | Q21: 20-F 2025 | R21: 20-F | S21: 2025 | T21: SEC EDGAR | U21: https://www.sec.gov/Archives/edgar/data/1167379/000116737926000014/alc-20251231.htm | V21: English | W21: 16328 | X21: Not in top half of Switzerland Health Care; Entrepreneurship 2 from Alcon Seed Fund supports the Eye Pitch Live pitch competition where en; red flag: none | Y21: coverage insufficient (cross_cultural); second look: no standalone report found
A22: Switzerland | B22: Industrials | C22: SCHN.SW | D22: Schindler Group | E22: 1 | F22: 2 | G22: 2 | H22: 1 | I22: =E22/5*35+F22/5*30+G22/5*20+H22/5*15 -> 30 | J22: 0 | K22: =MAX(0,I22-J22) -> 30 | L22: =COUNTIFS($A$2:$A$64,A22,$B$2:$B$64,B22,$K$2:$K$64,">"&K22)+1 -> 1 | M22: =IF(L22<=CEILING(COUNTIFS($A$2:$A$64,A22,$B$2:$B$64,B22)/2,1),"Pass","Fail") -> Pass | Q22: Annual report 2025 | R22: Annual report | S22: 2025 | T22: company website | U22: https://group.schindler.com/content/dam/website/group/docs/investors/2025/2025-schindler-fy-group-review-en.pdf/_jcr_content/renditions/original./2025-schindler-fy-group-review-en.pdf | V22: English | W22: 8316 | X22: Top half of Switzerland Industrials; Cross-cultural 2 from Accessibility features (induction loops, voice signaling, Braille) ins; red flag: none
A23: Switzerland | B23: Industrials | C23: ACLN.SW | D23: Accelleron Industries | E23: 0 | F23: 3 | G23: 2 | H23: 1 | I23: =E23/5*35+F23/5*30+G23/5*20+H23/5*15 -> 29 | J23: 0 | K23: =MAX(0,I23-J23) -> 29 | L23: =COUNTIFS($A$2:$A$64,A23,$B$2:$B$64,B23,$K$2:$K$64,">"&K23)+1 -> 2 | M23: =IF(L23<=CEILING(COUNTIFS($A$2:$A$64,A23,$B$2:$B$64,B23)/2,1),"Pass","Fail") -> Pass | Q23: Annual report 2025 | R23: Annual report | S23: 2025 | T23: company website | U23: https://accelleron.com/content/dam/accelleronind/documents/investors/accelleron-annual-report-2025.pdf | V23: English | W23: 39253 | X23: Top half of Switzerland Industrials; Community 3 from Group-wide employee-led community engagement program of volunteering a; red flag: none
A24: Switzerland | B24: Industrials | C24: BEAN.SW | D24: BELIMO Holding | E24: 0 | F24: 2 | G24: 3 | H24: 0 | I24: =E24/5*35+F24/5*30+G24/5*20+H24/5*15 -> 24 | J24: 0 | K24: =MAX(0,I24-J24) -> 24 | L24: =COUNTIFS($A$2:$A$64,A24,$B$2:$B$64,B24,$K$2:$K$64,">"&K24)+1 -> 3 | M24: =IF(L24<=CEILING(COUNTIFS($A$2:$A$64,A24,$B$2:$B$64,B24)/2,1),"Pass","Fail") -> Fail | Q24: Annual report 2025 | R24: Annual report | S24: 2025 | T24: company website | U24: https://report.belimo.com/ar25/app/uploads/Annual-Report-2025.pdf | V24: English | W24: 30231 | X24: Not in top half of Switzerland Industrials; Cross-cultural 3 from Participation in disability employment programs that bring people with; red flag: none
A25: Switzerland | B25: Industrials | C25: GEBN.SW | D25: Geberit | E25: 0 | F25: 2 | G25: 1 | H25: 1 | I25: =E25/5*35+F25/5*30+G25/5*20+H25/5*15 -> 19 | J25: 0 | K25: =MAX(0,I25-J25) -> 19 | L25: =COUNTIFS($A$2:$A$64,A25,$B$2:$B$64,B25,$K$2:$K$64,">"&K25)+1 -> 4 | M25: =IF(L25<=CEILING(COUNTIFS($A$2:$A$64,A25,$B$2:$B$64,B25)/2,1),"Pass","Fail") -> Fail | Q25: Annual report 2025 | R25: Annual report | S25: 2025 | T25: company website | U25: https://reports.geberit.com/annual-report/2025/_assets/downloads/geberit-ar25-en-entire.pdf | V25: English | W25: 39904 | X25: Not in top half of Switzerland Industrials; Community 2 from Internal GROW and LEAD talent and leadership development programmes fo; red flag: none; Discloses internally substantiated sexual harassment cases; not a red flag under the rule.
A26: Switzerland | B26: Materials | C26: GIVN.SW | D26: Givaudan | E26: 3 | F26: 3 | G26: 3 | H26: 2 | I26: =E26/5*35+F26/5*30+G26/5*20+H26/5*15 -> 57 | J26: 0 | K26: =MAX(0,I26-J26) -> 57 | L26: =COUNTIFS($A$2:$A$64,A26,$B$2:$B$64,B26,$K$2:$K$64,">"&K26)+1 -> 1 | M26: =IF(L26<=CEILING(COUNTIFS($A$2:$A$64,A26,$B$2:$B$64,B26)/2,1),"Pass","Fail") -> Pass | Q26: Annual report 2025 | R26: Annual report | S26: 2025 | T26: company website | U26: https://www.givaudan.com/file/1366761/download | V26: English | W26: 40036 | X26: Top half of Switzerland Materials; Cross-cultural 3 from Employee Community Groups for women, ethnic groups and LGBTQIA+ employ; red flag: none
A27: Switzerland | B27: Materials | C27: DSFIR.AS | D27: DSM-Firmenich | E27: 3 | F27: 3 | G27: 2 | H27: 2 | I27: =E27/5*35+F27/5*30+G27/5*20+H27/5*15 -> 53 | J27: 0 | K27: =MAX(0,I27-J27) -> 53 | L27: =COUNTIFS($A$2:$A$64,A27,$B$2:$B$64,B27,$K$2:$K$64,">"&K27)+1 -> 2 | M27: =IF(L27<=CEILING(COUNTIFS($A$2:$A$64,A27,$B$2:$B$64,B27)/2,1),"Pass","Fail") -> Pass | Q27: Annual report 2025 | R27: Annual report | S27: 2025 | T27: company website | U27: https://annualreport.dsm-firmenich.com/2025/_assets/downloads/entire-dsmfirmenich-iar25.pdf | V27: English | W27: 33840 | X27: Top half of Switzerland Materials; Creativity 3 from Perfumery & Beauty business unit creates fragrances for global and loc; red flag: none; Discloses internally substantiated discrimination and harassment cases; not a red flag under the rule.
A28: Switzerland | B28: Materials | C28: SIKA.SW | D28: Sika | E28: 1 | F28: 2 | G28: 2 | H28: 1 | I28: =E28/5*35+F28/5*30+G28/5*20+H28/5*15 -> 30 | J28: 0 | K28: =MAX(0,I28-J28) -> 30 | L28: =COUNTIFS($A$2:$A$64,A28,$B$2:$B$64,B28,$K$2:$K$64,">"&K28)+1 -> 3 | M28: =IF(L28<=CEILING(COUNTIFS($A$2:$A$64,A28,$B$2:$B$64,B28)/2,1),"Pass","Fail") -> Fail | Q28: Annual report 2025 | R28: Annual report | S28: 2025 | T28: company website | U28: https://www.sika.com/dam/dms/corporate/media/glo-ar-25-annual-report.pdf | V28: English | W28: 39707 | X28: Not in top half of Switzerland Materials; Cross-cultural 2 from Technical training and guidance for customers delivered in local langu; red flag: none; Discloses internally substantiated harassment cases; not a red flag under the rule.
A29: Taiwan | B29: Financials | C29: 2881.TW | D29: Fubon Financial | E29: 3 | F29: 3 | G29: 3 | H29: 2 | I29: =E29/5*35+F29/5*30+G29/5*20+H29/5*15 -> 57 | J29: 0 | K29: =MAX(0,I29-J29) -> 57 | L29: =COUNTIFS($A$2:$A$64,A29,$B$2:$B$64,B29,$K$2:$K$64,">"&K29)+1 -> 1 | M29: =IF(L29<=CEILING(COUNTIFS($A$2:$A$64,A29,$B$2:$B$64,B29)/2,1),"Pass","Fail") -> Pass | Q29: Annual report 2025 | R29: Annual report | S29: 2025 | T29: MOPS | U29: https://doc.twse.com.tw/pdf/2025_2881_20260612FE4_20261024_002816.pdf | V29: English | W29: 39709 | X29: Top half of Taiwan Financials; Cross-cultural 3 from Fubon Artistic Achievement Awards for the Disabled and All-Love Orches; red flag: none
A30: Taiwan | B30: Financials | C30: 2887.TW | D30: TS Financial Holding (formerly Taishin Financial Holdings) | E30: 3 | F30: 3 | G30: 3 | H30: 2 | I30: =E30/5*35+F30/5*30+G30/5*20+H30/5*15 -> 57 | J30: 0 | K30: =MAX(0,I30-J30) -> 57 | L30: =COUNTIFS($A$2:$A$64,A30,$B$2:$B$64,B30,$K$2:$K$64,">"&K30)+1 -> 1 | M30: =IF(L30<=CEILING(COUNTIFS($A$2:$A$64,A30,$B$2:$B$64,B30)/2,1),"Pass","Fail") -> Pass | Q30: Annual report 2025 | R30: Annual report | S30: 2025 | T30: MOPS | U30: https://doc.twse.com.tw/pdf/2025_2887_20260612FE4_20261024_001741.pdf | V30: English | W30: 23467 | X30: Top half of Taiwan Financials; Cross-cultural 3 from Nationwide ATM upgrade adding enlarged-font and barrier-free cardless ; red flag: none | Y30: TOC fallback (no usable table of contents): keyword paragraphs across the whole report; skipped 36 of 324 pages (risk, number pages, financial statements from page 325)
A31: Taiwan | B31: Financials | C31: 2883.TW | D31: KGI Financial Holding | E31: 2 | F31: 3 | G31: 2 | H31: 3 | I31: =E31/5*35+F31/5*30+G31/5*20+H31/5*15 -> 49 | J31: 0 | K31: =MAX(0,I31-J31) -> 49 | L31: =COUNTIFS($A$2:$A$64,A31,$B$2:$B$64,B31,$K$2:$K$64,">"&K31)+1 -> 3 | M31: =IF(L31<=CEILING(COUNTIFS($A$2:$A$64,A31,$B$2:$B$64,B31)/2,1),"Pass","Fail") -> Pass | Q31: Annual report 2025 | R31: Annual report | S31: 2025 | T31: MOPS | U31: https://doc.twse.com.tw/pdf/2025_2883_20260612FE4_20261024_002419.pdf | V31: English | W31: 27472 | X31: Top half of Taiwan Financials; Entrepreneurship 3 from 'Local Revitalizer+' program: skilled employee volunteers coach local ; red flag: none
A32: Taiwan | B32: Financials | C32: 2884.TW | D32: E.SUN Financial Holding | E32: 1 | F32: 3 | G32: 3 | H32: 3 | I32: =E32/5*35+F32/5*30+G32/5*20+H32/5*15 -> 46 | J32: 0 | K32: =MAX(0,I32-J32) -> 46 | L32: =COUNTIFS($A$2:$A$64,A32,$B$2:$B$64,B32,$K$2:$K$64,">"&K32)+1 -> 4 | M32: =IF(L32<=CEILING(COUNTIFS($A$2:$A$64,A32,$B$2:$B$64,B32)/2,1),"Pass","Fail") -> Fail | Q32: Annual report 2025 | R32: Annual report | S32: 2025 | T32: company website | U32: https://www.esunbank.com/en/-/media/ESUNFHC/Files/Investor-Relations/About-ESUN/Annual-Reports/Annual-Reports-FHC/esunfhc_annual_2025 | V32: English | W32: 40096 | X32: Not in top half of Taiwan Financials; Entrepreneurship 3 from Financial inclusion loan products, including micro-enterprise, young e; red flag: none
A33: Taiwan | B33: Financials | C33: 2890.TW | D33: Sinopac Financial Holdings | E33: 2 | F33: 3 | G33: 2 | H33: 2 | I33: =E33/5*35+F33/5*30+G33/5*20+H33/5*15 -> 46 | J33: 0 | K33: =MAX(0,I33-J33) -> 46 | L33: =COUNTIFS($A$2:$A$64,A33,$B$2:$B$64,B33,$K$2:$K$64,">"&K33)+1 -> 4 | M33: =IF(L33<=CEILING(COUNTIFS($A$2:$A$64,A33,$B$2:$B$64,B33)/2,1),"Pass","Fail") -> Fail | Q33: Annual report 2025 | R33: Annual report | S33: 2025 | T33: MOPS | U33: https://doc.twse.com.tw/pdf/2025_2890_20260526FE4_20261024_014510.pdf | V33: English | W33: 39921 | X33: Not in top half of Taiwan Financials; Community 3 from Company-wide employee training framework, including the SinoPac Univer; red flag: none
A34: Taiwan | B34: Financials | C34: 2885.TW | D34: Yuanta Financial Holding | E34: 2 | F34: 3 | G34: 2 | H34: 2 | I34: =E34/5*35+F34/5*30+G34/5*20+H34/5*15 -> 46 | J34: 0 | K34: =MAX(0,I34-J34) -> 46 | L34: =COUNTIFS($A$2:$A$64,A34,$B$2:$B$64,B34,$K$2:$K$64,">"&K34)+1 -> 4 | M34: =IF(L34<=CEILING(COUNTIFS($A$2:$A$64,A34,$B$2:$B$64,B34)/2,1),"Pass","Fail") -> Fail | Q34: Annual report 2025 | R34: Annual report | S34: 2025 | T34: company website | U34: https://www.yuanta.com/Files/970ac88b-be51-4dbd-8070-c3c680efcebe/YFH2025_E.pdf | V34: English | W34: 40186 | X34: Not in top half of Taiwan Financials; Community 3 from Yuanta Cultural and Educational Foundation runs a group-wide public we; red flag: none
A35: Taiwan | B35: Information Technology | C35: 2357.TW | D35: ASUS | E35: 3 | F35: 3 | G35: 3 | H35: 1 | I35: =E35/5*35+F35/5*30+G35/5*20+H35/5*15 -> 54 | J35: 0 | K35: =MAX(0,I35-J35) -> 54 | L35: =COUNTIFS($A$2:$A$64,A35,$B$2:$B$64,B35,$K$2:$K$64,">"&K35)+1 -> 1 | M35: =IF(L35<=CEILING(COUNTIFS($A$2:$A$64,A35,$B$2:$B$64,B35)/2,1),"Pass","Fail") -> Pass | Q35: Annual report 2025 | R35: Annual report | S35: 2025 | T35: company website | U35: https://www.asus.com/EVENT/Investor/Content/attachment_en/2025_Annual_Report_en.pdf | V35: English | W35: 30478 | X35: Top half of Taiwan Information Technology; Cross-cultural 3 from Sponsoring instructor fees for an art collective of autistic youth and; red flag: none; Discloses internally substantiated unspecified human rights risk incidents (harassment and workplace bullying handling described) cases; not a red flag under the rule.
A36: Taiwan | B36: Information Technology | C36: 2454.TW | D36: MediaTek | E36: 2 | F36: 3 | G36: 2 | H36: 2 | I36: =E36/5*35+F36/5*30+G36/5*20+H36/5*15 -> 46 | J36: 0 | K36: =MAX(0,I36-J36) -> 46 | L36: =COUNTIFS($A$2:$A$64,A36,$B$2:$B$64,B36,$K$2:$K$64,">"&K36)+1 -> 2 | M36: =IF(L36<=CEILING(COUNTIFS($A$2:$A$64,A36,$B$2:$B$64,B36)/2,1),"Pass","Fail") -> Pass | Q36: Annual report 2025 | R36: Annual report | S36: 2025 | T36: company website | U36: https://www.mediatek.com/hubfs/728015/MediaTek%20Assets/Pdfs/Annual%20Reports/2025-English-Annual-Report.pdf | V36: English | W36: 31141 | X36: Top half of Taiwan Information Technology; Community 3 from Nanzhou Sustainable Plan: sponsored education and culture program in a; red flag: none
A37: Taiwan | B37: Information Technology | C37: 2395.TW | D37: Advantech | E37: 2 | F37: 3 | G37: 2 | H37: 1 | I37: =E37/5*35+F37/5*30+G37/5*20+H37/5*15 -> 43 | J37: 0 | K37: =MAX(0,I37-J37) -> 43 | L37: =COUNTIFS($A$2:$A$64,A37,$B$2:$B$64,B37,$K$2:$K$64,">"&K37)+1 -> 3 | M37: =IF(L37<=CEILING(COUNTIFS($A$2:$A$64,A37,$B$2:$B$64,B37)/2,1),"Pass","Fail") -> Pass | Q37: Annual report 2025 | R37: Annual report | S37: 2025 | T37: MOPS | U37: https://doc.twse.com.tw/pdf/2025_2395_20260529FE4_20261024_015050.pdf | V37: English | W37: 30307 | X37: Top half of Taiwan Information Technology; Community 3 from Advantech Foundation funds arts and culture promotion, sustainable edu; red flag: none
A38: Taiwan | B38: Information Technology | C38: 3481.TW | D38: Innolux | E38: 2 | F38: 3 | G38: 2 | H38: 1 | I38: =E38/5*35+F38/5*30+G38/5*20+H38/5*15 -> 43 | J38: 0 | K38: =MAX(0,I38-J38) -> 43 | L38: =COUNTIFS($A$2:$A$64,A38,$B$2:$B$64,B38,$K$2:$K$64,">"&K38)+1 -> 3 | M38: =IF(L38<=CEILING(COUNTIFS($A$2:$A$64,A38,$B$2:$B$64,B38)/2,1),"Pass","Fail") -> Pass | Q38: Annual report 2025 | R38: Annual report | S38: 2025 | T38: MOPS | U38: https://doc.twse.com.tw/pdf/2025_3481_20260527FE4_20261024_015318.pdf | V38: English | W38: 37013 | X38: Top half of Taiwan Information Technology; Community 3 from Net Zero Education Walk Start Plan: environmental education courses an; red flag: none
A39: Taiwan | B39: Information Technology | C39: 3034.TW | D39: Novatek Microelectronics | E39: 2 | F39: 3 | G39: 2 | H39: 1 | I39: =E39/5*35+F39/5*30+G39/5*20+H39/5*15 -> 43 | J39: 0 | K39: =MAX(0,I39-J39) -> 43 | L39: =COUNTIFS($A$2:$A$64,A39,$B$2:$B$64,B39,$K$2:$K$64,">"&K39)+1 -> 3 | M39: =IF(L39<=CEILING(COUNTIFS($A$2:$A$64,A39,$B$2:$B$64,B39)/2,1),"Pass","Fail") -> Pass | Q39: Annual report 2025 | R39: Annual report | S39: 2025 | T39: company website | U39: https://www.novatek.com.tw/upload/website/_2025 Annual Report_e_26050614_856.pdf | V39: English | W39: 20252 | X39: Top half of Taiwan Information Technology; Community 3 from Novatek Educational Foundation scholarships for science education and ; red flag: none
A40: Taiwan | B40: Information Technology | C40: 3008.TW | D40: Largan Precision | E40: 0 | F40: 3 | G40: 1 | H40: 1 | I40: =E40/5*35+F40/5*30+G40/5*20+H40/5*15 -> 25 | J40: 0 | K40: =MAX(0,I40-J40) -> 25 | L40: =COUNTIFS($A$2:$A$64,A40,$B$2:$B$64,B40,$K$2:$K$64,">"&K40)+1 -> 6 | M40: =IF(L40<=CEILING(COUNTIFS($A$2:$A$64,A40,$B$2:$B$64,B40)/2,1),"Pass","Fail") -> Fail | Q40: Annual report 2025 | R40: Annual report | S40: 2025 | T40: company website | U40: https://www.largan.com.tw/en/tool-download/page_en_size/file/204/2025%20Company%20Annual%20Report | V40: English | W40: 13106 | X40: Not in top half of Taiwan Information Technology; Community 3 from Campus seminars held at schools to connect students with industry; red flag: none
...

Sheet Evidence quotes
A1: Country | B1: Sector | C1: Ticker | D1: Company | E1: Type | F1: Themes / flag | G1: Activity | H1: Quote (word for word, checked by code) | I1: English translation | J1: Section | K1: Source
A2: Denmark | B2: Financials | C2: ALSYDB.CO | D2: AL Sydbank A/S | E2: Evidence | F2: community: external_education | G2: Employees visit schools nationwide during Money Week to teach financial literacy classes | H2: During this week employees from AL Sydbank visit schools throughout the country to teach classes in financial literacy. | J2: Annual report > S – Social Information > AL Sydbank’s employees > Focus on personal finances during Money Week | K2: filing
A3: Denmark | B3: Financials | C3: ALSYDB.CO | D3: AL Sydbank A/S | E3: Evidence | F3: cross_cultural: internal_practice | G3: Workplace aids for employees with special needs | H3: In addition the health and safety manual contains a description of various aids for employees with special needs. | J3: Annual report > S – Social Information > Well-being and security for employees | K3: filing
A4: Denmark | B4: Financials | C4: ALSYDB.CO | D4: AL Sydbank A/S | E4: Evidence | F4: cross_cultural: demographics_only | G4: Gender balance target for management positions met in 2025 | H4: AL Sydbank’s overall objective is to achieve an equal gender balance among all managers and in 2025 we achieved the subtarget that the underrepresented gender will account for at least 35% of all employees in management positions in 2025. | J4: Annual report > S – Social Information > Diversity | K4: filing
A5: Denmark | B5: Financials | C5: ALSYDB.CO | D5: AL Sydbank A/S | E5: Evidence | F5: community: employee_development | G5: Competence mapping and talent development initiative for employees | H5: In 2025 determined efforts were made at AL Sydbank to identify employees’ competences and build the foundations for talent development. | J5: Annual report > S – Social Information > AL Sydbank’s employees > Talent development | K5: filing
A6: Denmark | B6: Financials | C6: ALSYDB.CO | D6: AL Sydbank A/S | E6: Evidence | F6: community: employee_development | G6: Regional trust-building communication project with additional adviser training | H6: Advisers receive additional training in customer contact in order to strengthen their relationship with customers and ensure that advice is based on trust, understanding and being present. | J6: Annual report > S – Social Information > Trust-building communication as a strategic project | K6: filing
A7: Denmark | B7: Financials | C7: ALSYDB.CO | D7: AL Sydbank A/S | E7: Evidence | F7: community: external_education | G7: Public 'Stop svindlerne' events teaching people to protect themselves against financial fraud | H7: AL Sydbank organises “Stop svindlerne” (Stop the fraudsters) events regularly where participants can learn how to protect themselves against financial fraud. | J7: Annual report > S – Social Information > Fighting crime > Efforts to combat IT fraud | K7: filing
A8: Denmark | B8: Financials | C8: ALSYDB.CO | D8: AL Sydbank A/S | E8: Evidence | F8: community: community_investment | G8: Sponsorships of clubs, associations, students and unions nationwide, mainly team and grassroots sports | H8: AL Sydbank supports via sponsorships small and large clubs and associations, students and unions across the country – primarily within team sports and grassroot sports. | J8: Annual report > Business model > Local presence > Local support | K8: filing
A9: Denmark | B9: Financials | C9: ALSYDB.CO | D9: AL Sydbank A/S | E9: Evidence | F9: community: community_investment | G9: Donations to charitable cultural, popular and educational purposes through several affiliated foundations | H9: AL Sydbank makes donations to charitable cultural, popular and educational purposes via the charitable foundations the Sydbank Foundation, Arbejdernes Landsbanks Fond, Trelleborg Fonden, Den Jyske Sparekasses Støttefonde, Jelling Sparekasses Fond, Fonden for Sparekassen Farsø as well as Fonden for Sparekassen i Skals. | J9: Annual report > Business model > Local presence > Local support | K9: filing
A10: Denmark | B10: Financials | C10: ALSYDB.CO | D10: AL Sydbank A/S | E10: Evidence | F10: community: community_investment | G10: Proposed donation to the Sydbank Foundation, subject to the annual general meeting | H10: The Board of Directors will propose to the annual general meeting that a dividend of DKK 25 per share, totalling DKK 2,145m, be distributed and that DKK 18m be donated to the Sydbank Foundation. | J10: Annual report > Financial review > Proposed dividend | K10: filing
A11: Denmark | B11: Financials | C11: ALSYDB.CO | D11: AL Sydbank A/S | E11: Evidence | F11: cross_cultural: customer_access | G11: Dedicated Sunflower phone line where trained staff assist customers with special needs | H11: For instance, in 2025 we set up a special Sunflower line where customers are assisted by employees who are mindful that these customers have special needs. | J11: Annual report > S – Social Information > Digitalisation | K11: filing
A12: Denmark | B12: Financials | C12: ALSYDB.CO | D12: AL Sydbank A/S | E12: Evidence | F12: cross_cultural: customer_access | G12: Digital banking platforms adapted for visually and hearing impaired customers | H12: We have also developed our digital platforms so that greater consideration is given to the visually impaired and the hearing impaired. | J12: Annual report > S – Social Information > Digitalisation | K12: filing
A13: Denmark | B13: Financials | C13: ALSYDB.CO | D13: AL Sydbank A/S | E13: Evidence | F13: cross_cultural: customer_access | G13: Free cash deposits and withdrawals for all retail clients with a NemKonto account | H13: This also means that all retail clients with a NemKonto account at our bank have the possibility to deposit and withdraw money free of charge. | J13: Annual report > Business model > The Bank’s customers | K13: filing
... A28: Denmark | B28: Financials | C28: DANSKE.CO | D28: Danske Bank | E28: Internal finding (no deduction) | F28: rights_finding (found by: internal) | G28: Internal whistleblowing reports of discrimination, bullying or harassment logged in 2025. The report does not say how many were substantiated. It states no material fines, penalties or severe human rights incidents, and no outside finding. Recorded for the team's note only; it costs no points. | H28: In terms of incidents and complaints reported through our whistleblowing system, 26 incidents related to discrimination within the Group’s workforce were logged in 2025 (2024: 16 incidents). | J28: Annual report > Sustainability Statement > Own workforce > Culture and Engagement Survey (CES) | K28: filing
A29: Denmark | B29: Financials | C29: DJUR.CO | D29: Djurslands Bank A/S | E29: Evidence | F29: community: employee_development | G29: Structured professional and personal skills development for all employees, with job profiles, personal development plans and at least four yearly development meetings (SUM) | H29: Banken arbejder systematiseret med faglig og personlig kompetenceudvikling af de enkelte medarbejdere. | I29: The bank works systematically with the professional and personal skills development of individual employees. | J29: Annual report > Ledelsesberetning > Forretningsmodel og strategi > Medarbejdere | K29: filing
A30: Denmark | B30: Financials | C30: DJUR.CO | D30: Djurslands Bank A/S | E30: Evidence | F30: community: external_education | G30: Takes in financial economist and finance bachelor students as interns every year, leading toward trainee positions | H30: Djurslands Bank prioriterer højt at tage ansvar for at uddanne fremtidens bankmedarbejdere, og vi tager hvert år imod finansøkonom- og finansbachelorstuderende i praktik. | I30: Djurslands Bank gives high priority to taking responsibility for educating future bank employees, and every year we take in financial economist and finance bachelor students as interns. | J30: Annual report > Ledelsesberetning > Forretningsmodel og strategi > Strategiske kundegrupper > For unge, af unge | K30: filing
A31: Denmark | B31: Financials | C31: DJUR.CO | D31: Djurslands Bank A/S | E31: Evidence | F31: community: community_investment | G31: Sponsors local activities and associations, including naming sponsorships of sports arenas in four towns and main sponsorship of a handball club | H31: Vi er aktive i lokalsamfundet og støtter synligt lokale aktiviteter og foreninger. | I31: We are active in the local community and visibly support local activities and associations. | J31: Annual report > Ledelsesberetning > Samfundsansvar > Lokalsamfundet | K31: filing
A32: Denmark | B32: Financials | C32: DJUR.CO | D32: Djurslands Bank A/S | E32: Evidence | F32: cross_cultural: internal_practice | G32: Statutory gender-balance measures, including extra focus on the career wishes of employees of the underrepresented gender in the annual development talk | H32: Der vil for det underrepræsenterede køns medarbejdere være ekstra fokus på området ”Hvilke udfordringer ønsker du i fremtiden?” i den årlige udviklingssamtale. | I32: For employees of the underrepresented gender there will be extra focus on the topic 'Which challenges do you want in the future?' in the annual development talk. | J32: Annual report > Ledelsesberetning > Selskabsledelse > Kønsfordeling | K32: filing
A33: Denmark | B33: Financials | C33: DJUR.CO | D33: Djurslands Bank A/S | E33: Evidence | F33: entrepreneurship: serving | G33: Ordinary banking services for business customers, including SMEs | H33: Banken rådgiver og servicerer 64.962 private kunder og 5.536 erhvervsvirksomheder og offentlige institutioner, samt 1.170 foreningskunder. | I33: The bank advises and serves 64,962 private customers and 5,536 businesses and public institutions, as well as 1,170 association customers. | J33: Annual report > Ledelsesberetning > Forretningsmodel og strategi > Kunder | K33: filing
A34: Denmark | B34: Financials | C34: JYSK.CO | D34: Jyske Bank | E34: Evidence | F34: community: employee_development | G34: Additional sustainability-transition training offered to a significant share of customer-facing employees | H34: As part of Jyske Bank’s efforts to combat climate change, a significant share of customer-oriented employees are offered additional training, to help them enter the dialogue with and advise our customers on sustainable transition. | J34: Annual report > Sustainability > S1 Own workforce > Training and skills enhancement further develop employees | K34: filing
A35: Denmark | B35: Financials | C35: JYSK.CO | D35: Jyske Bank | E35: Evidence | F35: community: employee_development | G35: Training programme completed by all employee union representatives | H35: A total of 106 employees serve as union representatives, and they have all completed a training programme to be equipped for carrying out their duties. | J35: Annual report > Sustainability > S1 Own workforce > Finansforbundet, Jyske Bank Kreds | K35: filing
A36: Denmark | B36: Financials | C36: JYSK.CO | D36: Jyske Bank | E36: Evidence | F36: community: community_investment | G36: Ongoing involvement with and support for the Danish Finance Institute, an independent research institute in finance and economics | H36: Jyske Bank has been actively involved with the Danish Finance Institute (DFI) since its foundation in 2017 as part of our commitment to strengthening the financial sector in Denmark. | J36: Annual report > Sustainability > S1 Own workforce > Support for research in economics and finance | K36: filing
A37: Denmark | B37: Financials | C37: JYSK.CO | D37: Jyske Bank | E37: Evidence | F37: cross_cultural: customer_access | G37: Participation in the Sunflower programme to support customers with invisible disabilities, also included as a mandatory employee learning activity | H37: Jyske Bank remains part of the Sunflower programme, which helps to ensure a good customer experience for everyone, including customers who have an invisible disability. | J37: Annual report > Sustainability > S4 Consumers and end-users > The Sunflower programme | K37: filing
A38: Denmark | B38: Financials | C38: JYSK.CO | D38: Jyske Bank | E38: Evidence | F38: cross_cultural: customer_access | G38: Accessibility improvements to online banking, apps and documents, including testing with a visually impaired customer | H38: Jyske Bank is actively working to improve accessibility in its digital self-service solutions, so that all customers – regardless of any functional impairment – have equal access to online banking, apps and documents. | J38: Annual report > Sustainability > S4 Consumers and end-users > Accessibility and user involvement in digital solutions | K38: filing
A39: Denmark | B39: Financials | C39: JYSK.CO | D39: Jyske Bank | E39: Evidence | F39: cross_cultural: internal_practice | G39: Gender-balanced recruitment practice requiring both genders in first-round interviews | H39: In 2025, we succeeded in having both genders represented in 53% of interviews. | J39: Annual report > Sustainability > S1 Own workforce > Gender diversity | K39: filing
A40: Denmark | B40: Health Care | C40: CHEMM.CO | D40: ChemoMetec | E40: Evidence | F40: community: employee_development | G40: General development, training and upskilling offered to employees | H40: We also offer our employees decent and attractive working and employment conditions as well as regular development, training and upgrading of skills to ensure that they are able to meet the ever-increasing labour market demands and to help deliver on ChemoMetec’s strategy. | J40: Annual report > Sustainability > Social, employee-related and diversity matters | K40: filing
A41: Denmark | B41: Health Care | C41: CHEMM.CO | D41: ChemoMetec | E41: Evidence | F41: community: employee_development | G41: Ongoing specialist training for sales staff on automation and integrated solutions | H41: Selling our solutions requires a high level of technical expertise as well as an understanding of our customers’ operations, and as we increasingly focus on automation and integrated solutions, we are investing in specialist training for our staff on an ongoing basis. | J41: Annual report > Our business model > Specialised sales force and support | K41: filing
A42: Denmark | B42: Health Care | C42: CHEMM.CO | D42: ChemoMetec | E42: Evidence | F42: cross_cultural: demographics_only | G42: Disclosure of management-team gender composition | H42: At the end of the 2025/26 financial year, the Management team had 76% male and 24% female members. | J42: Annual report > Sustainability > Diversity on the Board of Directors and other management levels > Other management levels | K42: filing
A43: Denmark | B43: Health Care | C43: CHEMM.CO | D43: ChemoMetec | E43: Evidence | F43: entrepreneurship: serving | G43: Placing cell counting instruments with business incubators to build a position in the start-up segment | H43: Over a number of years, ChemoMetec has built an attractive market position in this segment by placing our instruments with incubators, and the focus is now on leveraging the new opportunities in the segment. | J43: Annual report > Performance in 2025/26 > Business performance > Business area 1 (LCB market) | K43: filing
A44: Denmark | B44: Health Care | C44: BAVA.CO | D44: Bavarian Nordic | E44: Evidence | F44: community: community_investment | G44: In-kind donation of mpox vaccine doses to Africa CDC and UNICEF for outbreak response in Uganda and Liberia | H44: As part of our partnership with African CDC and UNICEF, Bavarian Nordic has donated a total of 130,000 doses of our mpox vaccine to help strengthen outbreak response. | J44: Annual report > Sustainability statements > S4 Consumers and end-users > Access to vaccines > Action 1 > Donations | K44: filing
A45: Denmark | B45: Health Care | C45: BAVA.CO | D45: Bavarian Nordic | E45: Evidence | F45: cross_cultural: customer_access | G45: Lowest-price mpox vaccine access for low- and lower-middle-income countries through Gavi and UNICEF agreements | H45: Through these contracts, we have worked together with all aforementioned parties to ensure vaccine access with the lowest price for the 77 low- and lower-middle-income countries. | J45: Annual report > Sustainability statements > S4 Consumers and end-users > Access to vaccines > Action 1 > Mpox: Working with partners to reach populations in low- and lower-middle-income countries | K45: filing
